const PREFIX = "Returned error: ";

async function tryCatch(promise, message) {
    try {
        await promise;
        throw null;
    }
    catch (error) {
        assert(error, "Expected an error but did not get one");
        assert(error.message.startsWith(PREFIX + message), "Expected an error starting with '" + PREFIX + message + "' but got '" + error.message + "' instead");
    }
};

module.exports = {
    catchRevert            : async function(promise) {await tryCatch(promise, "VM Exception while processing transaction: revert");},
    catchOutOfGas          : async function(promise) {await tryCatch(promise, "out of gas"         );},
    catchInvalidJump       : async function(promise) {await tryCatch(promise, "invalid JUMP"       );},
    catchInvalidOpcode     : async function(promise) {await tryCatch(promise, "invalid opcode"     );},
    catchStackOverflow     : async function(promise) {await tryCatch(promise, "stack overflow"     );},
    catchStackUnderflow    : async function(promise) {await tryCatch(promise, "stack underflow"    );},
    catchStaticStateChange : async function(promise) {await tryCatch(promise, "static state change");},
	senderAccountNotRecognized : async function(promise) {await tryCatch(promise, "sender account not recognized");},
};